<?xml version="1.0"?>
<!--
Physical AI & Humanoid Robotics Textbook
Module 1, Chapter 3: URDF for Humanoids
Description: Complete humanoid robot description with torso, arms, legs, and head
Visualization: ros2 launch humanoid_description display.launch.py
-->
<robot name="humanoid">

  <!-- ========== MATERIALS ========== -->
  <material name="blue">
    <color rgba="0.2 0.2 0.8 1.0"/>
  </material>
  <material name="gray">
    <color rgba="0.5 0.5 0.5 1.0"/>
  </material>
  <material name="white">
    <color rgba="0.9 0.9 0.9 1.0"/>
  </material>
  <material name="red">
    <color rgba="0.8 0.2 0.2 1.0"/>
  </material>

  <!-- ========== BASE LINK (PELVIS) ========== -->
  <link name="base_link">
    <visual>
      <origin xyz="0 0 0" rpy="0 0 0"/>
      <geometry>
        <box size="0.25 0.3 0.15"/>
      </geometry>
      <material name="gray"/>
    </visual>
    <collision>
      <origin xyz="0 0 0" rpy="0 0 0"/>
      <geometry>
        <box size="0.25 0.3 0.15"/>
      </geometry>
    </collision>
    <inertial>
      <mass value="5.0"/>
      <inertia ixx="0.05" ixy="0" ixz="0" iyy="0.05" iyz="0" izz="0.03"/>
    </inertial>
  </link>

  <!-- ========== TORSO ========== -->
  <link name="torso_link">
    <visual>
      <origin xyz="0 0 0.2" rpy="0 0 0"/>
      <geometry>
        <box size="0.3 0.25 0.4"/>
      </geometry>
      <material name="blue"/>
    </visual>
    <collision>
      <origin xyz="0 0 0.2" rpy="0 0 0"/>
      <geometry>
        <box size="0.3 0.25 0.4"/>
      </geometry>
    </collision>
    <inertial>
      <origin xyz="0 0 0.2" rpy="0 0 0"/>
      <mass value="15.0"/>
      <inertia ixx="0.3" ixy="0" ixz="0" iyy="0.3" iyz="0" izz="0.15"/>
    </inertial>
  </link>

  <joint name="torso_joint" type="fixed">
    <parent link="base_link"/>
    <child link="torso_link"/>
    <origin xyz="0 0 0.075" rpy="0 0 0"/>
  </joint>

  <!-- ========== HEAD ========== -->
  <link name="head_link">
    <visual>
      <origin xyz="0 0 0.075" rpy="0 0 0"/>
      <geometry>
        <sphere radius="0.1"/>
      </geometry>
      <material name="white"/>
    </visual>
    <collision>
      <origin xyz="0 0 0.075" rpy="0 0 0"/>
      <geometry>
        <sphere radius="0.1"/>
      </geometry>
    </collision>
    <inertial>
      <origin xyz="0 0 0.075" rpy="0 0 0"/>
      <mass value="3.0"/>
      <inertia ixx="0.015" ixy="0" ixz="0" iyy="0.015" iyz="0" izz="0.015"/>
    </inertial>
  </link>

  <joint name="neck_pan_joint" type="revolute">
    <parent link="torso_link"/>
    <child link="head_link"/>
    <origin xyz="0 0 0.425" rpy="0 0 0"/>
    <axis xyz="0 0 1"/>
    <limit lower="-1.5" upper="1.5" effort="20" velocity="2.0"/>
    <dynamics damping="0.5" friction="0.1"/>
  </joint>

  <!-- Camera -->
  <link name="camera_link">
    <visual>
      <geometry>
        <box size="0.03 0.08 0.02"/>
      </geometry>
      <material name="gray"/>
    </visual>
    <collision>
      <geometry>
        <box size="0.03 0.08 0.02"/>
      </geometry>
    </collision>
    <inertial>
      <mass value="0.1"/>
      <inertia ixx="0.0001" ixy="0" ixz="0" iyy="0.0001" iyz="0" izz="0.0001"/>
    </inertial>
  </link>

  <joint name="camera_joint" type="fixed">
    <parent link="head_link"/>
    <child link="camera_link"/>
    <origin xyz="0.08 0 0.1" rpy="0 0 0"/>
  </joint>

  <!-- IMU -->
  <link name="imu_link">
    <visual>
      <geometry>
        <box size="0.02 0.02 0.01"/>
      </geometry>
      <material name="red"/>
    </visual>
    <inertial>
      <mass value="0.05"/>
      <inertia ixx="0.00001" ixy="0" ixz="0" iyy="0.00001" iyz="0" izz="0.00001"/>
    </inertial>
  </link>

  <joint name="imu_joint" type="fixed">
    <parent link="torso_link"/>
    <child link="imu_link"/>
    <origin xyz="0 0 0.2" rpy="0 0 0"/>
  </joint>

  <!-- ========== LEFT ARM ========== -->
  <link name="l_shoulder_link">
    <visual>
      <geometry>
        <sphere radius="0.05"/>
      </geometry>
      <material name="gray"/>
    </visual>
    <collision>
      <geometry>
        <sphere radius="0.05"/>
      </geometry>
    </collision>
    <inertial>
      <mass value="0.5"/>
      <inertia ixx="0.001" ixy="0" ixz="0" iyy="0.001" iyz="0" izz="0.001"/>
    </inertial>
  </link>

  <joint name="l_shoulder_pan_joint" type="revolute">
    <parent link="torso_link"/>
    <child link="l_shoulder_link"/>
    <origin xyz="0.17 0 0.35" rpy="0 0 0"/>
    <axis xyz="0 0 1"/>
    <limit lower="-2.0" upper="2.0" effort="50" velocity="2.0"/>
    <dynamics damping="0.5" friction="0.1"/>
  </joint>

  <link name="l_upper_arm_link">
    <visual>
      <origin xyz="0.1 0 0" rpy="0 1.5708 0"/>
      <geometry>
        <cylinder radius="0.04" length="0.2"/>
      </geometry>
      <material name="blue"/>
    </visual>
    <collision>
      <origin xyz="0.1 0 0" rpy="0 1.5708 0"/>
      <geometry>
        <cylinder radius="0.04" length="0.2"/>
      </geometry>
    </collision>
    <inertial>
      <origin xyz="0.1 0 0" rpy="0 0 0"/>
      <mass value="2.0"/>
      <inertia ixx="0.01" ixy="0" ixz="0" iyy="0.01" iyz="0" izz="0.005"/>
    </inertial>
  </link>

  <joint name="l_shoulder_lift_joint" type="revolute">
    <parent link="l_shoulder_link"/>
    <child link="l_upper_arm_link"/>
    <origin xyz="0 0 0" rpy="0 0 0"/>
    <axis xyz="0 1 0"/>
    <limit lower="-1.5" upper="1.5" effort="50" velocity="2.0"/>
    <dynamics damping="0.5" friction="0.1"/>
  </joint>

  <link name="l_forearm_link">
    <visual>
      <origin xyz="0.1 0 0" rpy="0 1.5708 0"/>
      <geometry>
        <cylinder radius="0.035" length="0.2"/>
      </geometry>
      <material name="blue"/>
    </visual>
    <collision>
      <origin xyz="0.1 0 0" rpy="0 1.5708 0"/>
      <geometry>
        <cylinder radius="0.035" length="0.2"/>
      </geometry>
    </collision>
    <inertial>
      <origin xyz="0.1 0 0" rpy="0 0 0"/>
      <mass value="1.5"/>
      <inertia ixx="0.008" ixy="0" ixz="0" iyy="0.008" iyz="0" izz="0.004"/>
    </inertial>
  </link>

  <joint name="l_elbow_joint" type="revolute">
    <parent link="l_upper_arm_link"/>
    <child link="l_forearm_link"/>
    <origin xyz="0.2 0 0" rpy="0 0 0"/>
    <axis xyz="0 1 0"/>
    <limit lower="0" upper="2.5" effort="30" velocity="2.0"/>
    <dynamics damping="0.3" friction="0.1"/>
  </joint>

  <link name="l_hand_link">
    <visual>
      <origin xyz="0.04 0 0" rpy="0 0 0"/>
      <geometry>
        <box size="0.08 0.06 0.03"/>
      </geometry>
      <material name="white"/>
    </visual>
    <collision>
      <origin xyz="0.04 0 0" rpy="0 0 0"/>
      <geometry>
        <box size="0.08 0.06 0.03"/>
      </geometry>
    </collision>
    <inertial>
      <origin xyz="0.04 0 0" rpy="0 0 0"/>
      <mass value="0.5"/>
      <inertia ixx="0.001" ixy="0" ixz="0" iyy="0.001" iyz="0" izz="0.001"/>
    </inertial>
  </link>

  <joint name="l_wrist_joint" type="revolute">
    <parent link="l_forearm_link"/>
    <child link="l_hand_link"/>
    <origin xyz="0.2 0 0" rpy="0 0 0"/>
    <axis xyz="1 0 0"/>
    <limit lower="-1.5" upper="1.5" effort="10" velocity="2.0"/>
    <dynamics damping="0.2" friction="0.1"/>
  </joint>

  <!-- ========== RIGHT ARM ========== -->
  <link name="r_shoulder_link">
    <visual>
      <geometry>
        <sphere radius="0.05"/>
      </geometry>
      <material name="gray"/>
    </visual>
    <collision>
      <geometry>
        <sphere radius="0.05"/>
      </geometry>
    </collision>
    <inertial>
      <mass value="0.5"/>
      <inertia ixx="0.001" ixy="0" ixz="0" iyy="0.001" iyz="0" izz="0.001"/>
    </inertial>
  </link>

  <joint name="r_shoulder_pan_joint" type="revolute">
    <parent link="torso_link"/>
    <child link="r_shoulder_link"/>
    <origin xyz="-0.17 0 0.35" rpy="0 0 0"/>
    <axis xyz="0 0 1"/>
    <limit lower="-2.0" upper="2.0" effort="50" velocity="2.0"/>
    <dynamics damping="0.5" friction="0.1"/>
  </joint>

  <link name="r_upper_arm_link">
    <visual>
      <origin xyz="-0.1 0 0" rpy="0 1.5708 0"/>
      <geometry>
        <cylinder radius="0.04" length="0.2"/>
      </geometry>
      <material name="blue"/>
    </visual>
    <collision>
      <origin xyz="-0.1 0 0" rpy="0 1.5708 0"/>
      <geometry>
        <cylinder radius="0.04" length="0.2"/>
      </geometry>
    </collision>
    <inertial>
      <origin xyz="-0.1 0 0" rpy="0 0 0"/>
      <mass value="2.0"/>
      <inertia ixx="0.01" ixy="0" ixz="0" iyy="0.01" iyz="0" izz="0.005"/>
    </inertial>
  </link>

  <joint name="r_shoulder_lift_joint" type="revolute">
    <parent link="r_shoulder_link"/>
    <child link="r_upper_arm_link"/>
    <origin xyz="0 0 0" rpy="0 0 0"/>
    <axis xyz="0 1 0"/>
    <limit lower="-1.5" upper="1.5" effort="50" velocity="2.0"/>
    <dynamics damping="0.5" friction="0.1"/>
  </joint>

  <link name="r_forearm_link">
    <visual>
      <origin xyz="-0.1 0 0" rpy="0 1.5708 0"/>
      <geometry>
        <cylinder radius="0.035" length="0.2"/>
      </geometry>
      <material name="blue"/>
    </visual>
    <collision>
      <origin xyz="-0.1 0 0" rpy="0 1.5708 0"/>
      <geometry>
        <cylinder radius="0.035" length="0.2"/>
      </geometry>
    </collision>
    <inertial>
      <origin xyz="-0.1 0 0" rpy="0 0 0"/>
      <mass value="1.5"/>
      <inertia ixx="0.008" ixy="0" ixz="0" iyy="0.008" iyz="0" izz="0.004"/>
    </inertial>
  </link>

  <joint name="r_elbow_joint" type="revolute">
    <parent link="r_upper_arm_link"/>
    <child link="r_forearm_link"/>
    <origin xyz="-0.2 0 0" rpy="0 0 0"/>
    <axis xyz="0 1 0"/>
    <limit lower="0" upper="2.5" effort="30" velocity="2.0"/>
    <dynamics damping="0.3" friction="0.1"/>
  </joint>

  <link name="r_hand_link">
    <visual>
      <origin xyz="-0.04 0 0" rpy="0 0 0"/>
      <geometry>
        <box size="0.08 0.06 0.03"/>
      </geometry>
      <material name="white"/>
    </visual>
    <collision>
      <origin xyz="-0.04 0 0" rpy="0 0 0"/>
      <geometry>
        <box size="0.08 0.06 0.03"/>
      </geometry>
    </collision>
    <inertial>
      <origin xyz="-0.04 0 0" rpy="0 0 0"/>
      <mass value="0.5"/>
      <inertia ixx="0.001" ixy="0" ixz="0" iyy="0.001" iyz="0" izz="0.001"/>
    </inertial>
  </link>

  <joint name="r_wrist_joint" type="revolute">
    <parent link="r_forearm_link"/>
    <child link="r_hand_link"/>
    <origin xyz="-0.2 0 0" rpy="0 0 0"/>
    <axis xyz="1 0 0"/>
    <limit lower="-1.5" upper="1.5" effort="10" velocity="2.0"/>
    <dynamics damping="0.2" friction="0.1"/>
  </joint>

  <!-- ========== LEFT LEG ========== -->
  <link name="l_hip_link">
    <visual>
      <geometry>
        <sphere radius="0.05"/>
      </geometry>
      <material name="gray"/>
    </visual>
    <collision>
      <geometry>
        <sphere radius="0.05"/>
      </geometry>
    </collision>
    <inertial>
      <mass value="1.0"/>
      <inertia ixx="0.002" ixy="0" ixz="0" iyy="0.002" iyz="0" izz="0.002"/>
    </inertial>
  </link>

  <joint name="l_hip_yaw_joint" type="revolute">
    <parent link="base_link"/>
    <child link="l_hip_link"/>
    <origin xyz="0 0.1 -0.075" rpy="0 0 0"/>
    <axis xyz="0 0 1"/>
    <limit lower="-0.5" upper="0.5" effort="100" velocity="2.0"/>
    <dynamics damping="0.5" friction="0.1"/>
  </joint>

  <link name="l_thigh_link">
    <visual>
      <origin xyz="0 0 -0.175" rpy="0 0 0"/>
      <geometry>
        <cylinder radius="0.05" length="0.35"/>
      </geometry>
      <material name="blue"/>
    </visual>
    <collision>
      <origin xyz="0 0 -0.175" rpy="0 0 0"/>
      <geometry>
        <cylinder radius="0.05" length="0.35"/>
      </geometry>
    </collision>
    <inertial>
      <origin xyz="0 0 -0.175" rpy="0 0 0"/>
      <mass value="5.0"/>
      <inertia ixx="0.06" ixy="0" ixz="0" iyy="0.06" iyz="0" izz="0.02"/>
    </inertial>
  </link>

  <joint name="l_hip_pitch_joint" type="revolute">
    <parent link="l_hip_link"/>
    <child link="l_thigh_link"/>
    <origin xyz="0 0 0" rpy="0 0 0"/>
    <axis xyz="0 1 0"/>
    <limit lower="-1.5" upper="0.5" effort="150" velocity="2.0"/>
    <dynamics damping="0.5" friction="0.1"/>
  </joint>

  <link name="l_shin_link">
    <visual>
      <origin xyz="0 0 -0.175" rpy="0 0 0"/>
      <geometry>
        <cylinder radius="0.04" length="0.35"/>
      </geometry>
      <material name="blue"/>
    </visual>
    <collision>
      <origin xyz="0 0 -0.175" rpy="0 0 0"/>
      <geometry>
        <cylinder radius="0.04" length="0.35"/>
      </geometry>
    </collision>
    <inertial>
      <origin xyz="0 0 -0.175" rpy="0 0 0"/>
      <mass value="3.0"/>
      <inertia ixx="0.04" ixy="0" ixz="0" iyy="0.04" iyz="0" izz="0.01"/>
    </inertial>
  </link>

  <joint name="l_knee_joint" type="revolute">
    <parent link="l_thigh_link"/>
    <child link="l_shin_link"/>
    <origin xyz="0 0 -0.35" rpy="0 0 0"/>
    <axis xyz="0 1 0"/>
    <limit lower="0" upper="2.5" effort="100" velocity="2.0"/>
    <dynamics damping="0.5" friction="0.1"/>
  </joint>

  <link name="l_foot_link">
    <visual>
      <origin xyz="0.05 0 -0.025" rpy="0 0 0"/>
      <geometry>
        <box size="0.2 0.1 0.05"/>
      </geometry>
      <material name="white"/>
    </visual>
    <collision>
      <origin xyz="0.05 0 -0.025" rpy="0 0 0"/>
      <geometry>
        <box size="0.2 0.1 0.05"/>
      </geometry>
    </collision>
    <inertial>
      <origin xyz="0.05 0 -0.025" rpy="0 0 0"/>
      <mass value="1.0"/>
      <inertia ixx="0.002" ixy="0" ixz="0" iyy="0.004" iyz="0" izz="0.005"/>
    </inertial>
  </link>

  <joint name="l_ankle_joint" type="revolute">
    <parent link="l_shin_link"/>
    <child link="l_foot_link"/>
    <origin xyz="0 0 -0.35" rpy="0 0 0"/>
    <axis xyz="0 1 0"/>
    <limit lower="-0.8" upper="0.8" effort="50" velocity="2.0"/>
    <dynamics damping="0.3" friction="0.1"/>
  </joint>

  <!-- ========== RIGHT LEG ========== -->
  <link name="r_hip_link">
    <visual>
      <geometry>
        <sphere radius="0.05"/>
      </geometry>
      <material name="gray"/>
    </visual>
    <collision>
      <geometry>
        <sphere radius="0.05"/>
      </geometry>
    </collision>
    <inertial>
      <mass value="1.0"/>
      <inertia ixx="0.002" ixy="0" ixz="0" iyy="0.002" iyz="0" izz="0.002"/>
    </inertial>
  </link>

  <joint name="r_hip_yaw_joint" type="revolute">
    <parent link="base_link"/>
    <child link="r_hip_link"/>
    <origin xyz="0 -0.1 -0.075" rpy="0 0 0"/>
    <axis xyz="0 0 1"/>
    <limit lower="-0.5" upper="0.5" effort="100" velocity="2.0"/>
    <dynamics damping="0.5" friction="0.1"/>
  </joint>

  <link name="r_thigh_link">
    <visual>
      <origin xyz="0 0 -0.175" rpy="0 0 0"/>
      <geometry>
        <cylinder radius="0.05" length="0.35"/>
      </geometry>
      <material name="blue"/>
    </visual>
    <collision>
      <origin xyz="0 0 -0.175" rpy="0 0 0"/>
      <geometry>
        <cylinder radius="0.05" length="0.35"/>
      </geometry>
    </collision>
    <inertial>
      <origin xyz="0 0 -0.175" rpy="0 0 0"/>
      <mass value="5.0"/>
      <inertia ixx="0.06" ixy="0" ixz="0" iyy="0.06" iyz="0" izz="0.02"/>
    </inertial>
  </link>

  <joint name="r_hip_pitch_joint" type="revolute">
    <parent link="r_hip_link"/>
    <child link="r_thigh_link"/>
    <origin xyz="0 0 0" rpy="0 0 0"/>
    <axis xyz="0 1 0"/>
    <limit lower="-1.5" upper="0.5" effort="150" velocity="2.0"/>
    <dynamics damping="0.5" friction="0.1"/>
  </joint>

  <link name="r_shin_link">
    <visual>
      <origin xyz="0 0 -0.175" rpy="0 0 0"/>
      <geometry>
        <cylinder radius="0.04" length="0.35"/>
      </geometry>
      <material name="blue"/>
    </visual>
    <collision>
      <origin xyz="0 0 -0.175" rpy="0 0 0"/>
      <geometry>
        <cylinder radius="0.04" length="0.35"/>
      </geometry>
    </collision>
    <inertial>
      <origin xyz="0 0 -0.175" rpy="0 0 0"/>
      <mass value="3.0"/>
      <inertia ixx="0.04" ixy="0" ixz="0" iyy="0.04" iyz="0" izz="0.01"/>
    </inertial>
  </link>

  <joint name="r_knee_joint" type="revolute">
    <parent link="r_thigh_link"/>
    <child link="r_shin_link"/>
    <origin xyz="0 0 -0.35" rpy="0 0 0"/>
    <axis xyz="0 1 0"/>
    <limit lower="0" upper="2.5" effort="100" velocity="2.0"/>
    <dynamics damping="0.5" friction="0.1"/>
  </joint>

  <link name="r_foot_link">
    <visual>
      <origin xyz="0.05 0 -0.025" rpy="0 0 0"/>
      <geometry>
        <box size="0.2 0.1 0.05"/>
      </geometry>
      <material name="white"/>
    </visual>
    <collision>
      <origin xyz="0.05 0 -0.025" rpy="0 0 0"/>
      <geometry>
        <box size="0.2 0.1 0.05"/>
      </geometry>
    </collision>
    <inertial>
      <origin xyz="0.05 0 -0.025" rpy="0 0 0"/>
      <mass value="1.0"/>
      <inertia ixx="0.002" ixy="0" ixz="0" iyy="0.004" iyz="0" izz="0.005"/>
    </inertial>
  </link>

  <joint name="r_ankle_joint" type="revolute">
    <parent link="r_shin_link"/>
    <child link="r_foot_link"/>
    <origin xyz="0 0 -0.35" rpy="0 0 0"/>
    <axis xyz="0 1 0"/>
    <limit lower="-0.8" upper="0.8" effort="50" velocity="2.0"/>
    <dynamics damping="0.3" friction="0.1"/>
  </joint>

</robot>
